<?xml version="1.0"?>
<robot xmlns:xacro="http://www.ros.org/wiki/xacro" name="articulated_amr">

    <!-- Include Gazebo Plugins -->
    <xacro:include filename="gazebo_plugins.xacro" />

    <!-- Core Colors -->
    <material name="chassis_color"><color rgba="0.2 0.2 0.8 1"/></material>
    <material name="wheel_color"><color rgba="0.1 0.1 0.1 1"/></material>
    <material name="caster_color"><color rgba="0.5 0.5 0.5 1"/></material>
    <material name="sensor_color"><color rgba="0.9 0.1 0.1 1"/></material>

    <!-- Inertial Macros -->
    <xacro:macro name="inertial_box" params="mass x y z *origin">
        <inertial>
            <xacro:insert_block name="origin"/>
            <mass value="${mass}" />
            <inertia ixx="${(1/12) * mass * (y*y + z*z)}" ixy="0.0" ixz="0.0"
                     iyy="${(1/12) * mass * (x*x + z*z)}" iyz="0.0"
                     izz="${(1/12) * mass * (x*x + y*y)}" />
        </inertial>
    </xacro:macro>

    <xacro:macro name="inertial_cylinder" params="mass length radius *origin">
        <inertial>
            <xacro:insert_block name="origin"/>
            <mass value="${mass}" />
            <inertia ixx="${(1/12) * mass * (3*radius*radius + length*length)}" ixy="0.0" ixz="0.0"
                     iyy="${(1/12) * mass * (3*radius*radius + length*length)}" iyz="0.0"
                     izz="${(1/2) * mass * (radius*radius)}" />
        </inertial>
    </xacro:macro>

    <xacro:macro name="inertial_sphere" params="mass radius *origin">
        <inertial>
            <xacro:insert_block name="origin"/>
            <mass value="${mass}" />
            <inertia ixx="${(2/5) * mass * (radius*radius)}" ixy="0.0" ixz="0.0"
                     iyy="${(2/5) * mass * (radius*radius)}" iyz="0.0"
                     izz="${(2/5) * mass * (radius*radius)}" />
        </inertial>
    </xacro:macro>

    <!-- Base Footprint (Ground Projection for Nav2) -->
    <link name="base_footprint"/>

    <joint name="base_footprint_joint" type="fixed">
        <parent link="base_footprint"/>
        <child link="base_link"/>
        <origin xyz="0 0 0.05" rpy="0 0 0"/>
    </joint>

    <!-- Base Link (Chassis Center) -->
    <link name="base_link">
        <visual>
            <origin xyz="0.15 0 0.075"/>
            <geometry>
                <box size="0.4 0.3 0.15"/>
            </geometry>
            <material name="chassis_color"/>
        </visual>
        <collision>
            <origin xyz="0.15 0 0.075"/>
            <geometry>
                <box size="0.4 0.3 0.15"/>
            </geometry>
        </collision>
        <xacro:inertial_box mass="5.0" x="0.4" y="0.3" z="0.15">
            <origin xyz="0.15 0 0.075" rpy="0 0 0"/>
        </xacro:inertial_box>
    </link>

    <!-- Left Wheel -->
    <joint name="left_wheel_joint" type="continuous">
        <parent link="base_link"/>
        <child link="left_wheel"/>
        <origin xyz="0 0.175 0" rpy="-${pi/2} 0 0"/>
        <axis xyz="0 0 1"/>
    </joint>

    <link name="left_wheel">
        <visual>
            <geometry><cylinder radius="0.05" length="0.04"/></geometry>
            <material name="wheel_color"/>
        </visual>
        <collision>
            <geometry><cylinder radius="0.05" length="0.04"/></geometry>
        </collision>
        <xacro:inertial_cylinder mass="0.5" length="0.04" radius="0.05">
            <origin xyz="0 0 0" rpy="0 0 0"/>
        </xacro:inertial_cylinder>
    </link>

    <!-- Right Wheel -->
    <joint name="right_wheel_joint" type="continuous">
        <parent link="base_link"/>
        <child link="right_wheel"/>
        <origin xyz="0 -0.175 0" rpy="${pi/2} 0 0"/>
        <axis xyz="0 0 -1"/>
    </joint>

    <link name="right_wheel">
        <visual>
            <geometry><cylinder radius="0.05" length="0.04"/></geometry>
            <material name="wheel_color"/>
        </visual>
        <collision>
            <geometry><cylinder radius="0.05" length="0.04"/></geometry>
        </collision>
        <xacro:inertial_cylinder mass="0.5" length="0.04" radius="0.05">
            <origin xyz="0 0 0" rpy="0 0 0"/>
        </xacro:inertial_cylinder>
    </link>

    <!-- Caster Wheel -->
    <joint name="caster_wheel_joint" type="fixed">
        <parent link="base_link"/>
        <child link="caster_wheel"/>
        <origin xyz="0.28 0 -0.025"/>
    </joint>

    <link name="caster_wheel">
        <visual>
            <geometry><sphere radius="0.025"/></geometry>
            <material name="caster_color"/>
        </visual>
        <collision>
            <geometry><sphere radius="0.025"/></geometry>
        </collision>
        <xacro:inertial_sphere mass="0.1" radius="0.025">
            <origin xyz="0 0 0" rpy="0 0 0"/>
        </xacro:inertial_sphere>
    </link>

    <!-- LiDAR Frame -->
    <joint name="laser_joint" type="fixed">
        <parent link="base_link"/>
        <child link="laser_frame"/>
        <origin xyz="0.1 0 0.175" rpy="0 0 0"/>
    </joint>

    <link name="laser_frame">
        <visual>
            <geometry><cylinder radius="0.03" length="0.04"/></geometry>
            <material name="sensor_color"/>
        </visual>
        <collision>
            <geometry><cylinder radius="0.03" length="0.04"/></geometry>
        </collision>
        <xacro:inertial_cylinder mass="0.1" length="0.04" radius="0.03">
            <origin xyz="0 0 0" rpy="0 0 0"/>
        </xacro:inertial_cylinder>
    </link>

    <!-- Camera Frame -->
    <joint name="camera_joint" type="fixed">
        <parent link="base_link"/>
        <child link="camera_frame"/>
        <origin xyz="0.35 0 0.12" rpy="0 0 0"/>
    </joint>

    <link name="camera_frame">
        <visual>
            <geometry><box size="0.02 0.08 0.03"/></geometry>
            <material name="sensor_color"/>
        </visual>
        <collision>
            <geometry><box size="0.02 0.08 0.03"/></geometry>
        </collision>
        <xacro:inertial_box mass="0.05" x="0.02" y="0.08" z="0.03">
            <origin xyz="0 0 0" rpy="0 0 0"/>
        </xacro:inertial_box>
    </link>

    <!-- Optical Joint for Standard Camera Image Frames -->
    <joint name="camera_optical_joint" type="fixed">
        <parent link="camera_frame"/>
        <child link="camera_link_optical"/>
        <origin xyz="0 0 0" rpy="-${pi/2} 0 -${pi/2}"/>
    </joint>
    <link name="camera_link_optical"/>

</robot>